Workbook

Sheet 요약
A1: PathWave 개발 체크리스트 요약
A3: 지표 | B3: 값
A4: 총 PR 수 (Phase 1) | B4: =COUNTA('Phase 1 PR 체크리스트'!A2:A30)
A5: 완료 (✅) | B5: =COUNTIF('Phase 1 PR 체크리스트'!F2:F30,"✅")
A6: 부분 완료 (◑) | B6: =COUNTIF('Phase 1 PR 체크리스트'!F2:F30,"◑")
A7: 진행중 (🔄) | B7: =COUNTIF('Phase 1 PR 체크리스트'!F2:F30,"🔄")
A8: 검토중 (🔎) | B8: =COUNTIF('Phase 1 PR 체크리스트'!F2:F30,"🔎")
A9: 대기 (⬜) | B9: =COUNTIF('Phase 1 PR 체크리스트'!F2:F30,"⬜")
A10: 가중 평균 진척율 | B10: =AVERAGE('Phase 1 PR 체크리스트'!G2:G30)
A11: 업데이트 일자 | B11: 2026-05-23
A12: 외부 서비스 신청 시작 | B12: 2026-06-02 주 (법인카드 수취 후)
A13: 목표 출시일 | B13: 2026-07-하순~8월 초
A14: 사용 방법
A15: ① "기능별 전체 현황": 도메인별 이전 완료/Phase 1/남은 작업을 한눈에
A16: ② "Phase 1 PR 체크리스트": F열 상태 드롭다운(⬜→🔄→🔎→◑→✅) 갱신
A17: ③ 진척율 자동 계산: ⬜=0% · 🔄=50% · ◑=70% · 🔎=90% · ✅=100%
A18: ④ "단계별 일정": 출시까지의 큰 그림 일정
A19: ⑤ 요약은 PR 체크리스트 상태를 실시간 집계

Sheet 기능별 전체 현황
A1: PathWave 기능별 전체 작업 현황 — 이전 완료 + Phase 1 진행 + 남은 작업
A3: 도메인/기능 | B3: 단계 | C3: 항목 | D3: 내용 | E3: 상태 | F3: 비고
A4: 인증/회원가입 | B4: 이전 완료 | C4: PR #1~#5, #28, #45, #55 | D4: 이메일 가입·로그인, 5종 소셜 로그인(Google/Apple/Facebook/Kakao/Naver), 동의 단계, 미성년자 보호, 회원 탈퇴 흐름 | E4: ✅ | F4: 코드 완료, 실 키는 서비스 가입 후
A5: 인증/회원가입 | B5: Phase 1 | C5: P4 | D5: dev 인증 우회 제거 + 실 로그인폼 복구 + /forgot-password 정식 구현 | E5: ✅ | F5: BE 2 API + provider 페이지
A6: 인증/회원가입 | B6: 남은 | C6: 실 키 검증 | D6: Firebase·카카오·네이버 실 키로 통합 테스트 (서비스 가입 후) | E6: ⬜ | F6: 외부 서비스 활성화 후
A7: 매장 정보 | B7: 이전 완료 | C7: PR #2, #14, #16 | D7: 매장 CRUD, 이미지 갤러리, 다국어 번역 캐시 | E7: ✅
A8: 매장 정보 | B8: Phase 1 | C8: P5 | D8: StoreInfo 하드코딩 제거 + StoreService 실연동 + PwFooter + dead code 정리 | E8: ✅ | F8: 백엔드 schema 부재(category/holidays) → P8c 별도 작업
A9: 매장 정보 | B9: 남은 | C9: P8c (별도 작업 칩) | D9: facilities 스키마 category/holidays/detailAddress 컬럼 추가 또는 UI 정리 | E9: ⬜ | F9: 결정 필요
A10: 결제·구독 | B10: 이전 완료 | C10: PR #39, #41, #43~46, #56 | D10: billing API 전체(cards/subscriptions/payments/refund/extend), PG provider 추상화 | E10: ✅ | F10: 백엔드 sim 모드 — 토스 키 활성화 시 운영
A11: 결제·구독 | B11: Phase 1 | C11: P7 | D11: provider 카드 평문저장 제거(PCI) + BillingService + Payment/Subscription/ServiceRequest 실연동 | E11: ✅ | F11: admin Payments는 이미 정합
A12: 결제·구독 | B12: 남은 | C12: 토스 키 활성화 | D12: 토스페이먼츠 가맹점 심사 통과 후 PG_PROVIDER=toss + 실 결제 검증 | E12: ⬜ | F12: 외부(심사 1~2주)
A13: 쿠폰·스탬프 | B13: 이전 완료 | C13: PR #6, #18, #22, #29 | D13: 쿠폰 발행/사용/만료, 스탬프 적립/리워드, 정책 설정 | E13: ✅
A14: 쿠폰·스탬프 | B14: Phase 1 | C14: P9 | D14: provider Coupons·Stamps mock→실연동 + mobile 쿠폰 사용 silent error 수정 | E14: ⬜
A15: 쿠폰·스탬프 | B15: Phase 1 | C15: P22 | D15: 회원 QR (URL 토큰 인코딩) + provider 스캔/코드입력 → 적립/사용 + 친구초대 QR/링크 | E15: ⬜ | F15: P9 이후 병행
A16: 채팅 | B16: 이전 완료 | C16: PR #16, #21, #142 | D16: 1:1 채팅 rooms/messages, SSE 스트림, 신고/차단 | E16: ✅
A17: 채팅 | B17: Phase 1 | C17: P8 (◑) | D17: provider CustomerChat 실연동 + admin ChatMonitor + BE /api/chat/reports + mobile SSE 재연결 | E17: ◑ | F17: ⚠ app.py 재시작 후 활성
A18: 채팅 | B18: 남은 | C18: P8b | D18: 채팅 자동 번역(번역 캐시 스키마 + 뷰어별 언어 + translator 연결) | E18: ⬜ | F18: DeepL/Google Translate 키 확보 후
A19: 알림 (Inbox + Push) | B19: 이전 완료 | C19: PR #38, #44, #50 | D19: Inbox·Announcements, FCM 푸시, APNs(HTTP/2 JWT), 알림 선호 카테고리 | E19: ✅
A20: 알림 (Inbox + Push) | B20: Phase 1 | C20: P10 | D20: provider Notifications 실연동 + mobile 알림 라우팅 + 알림 탭 보강 | E20: ⬜
A21: WiFi (1회 연결) | B21: 이전 완료 | C21: PR #11, #49 | D21: wifi_profiles 기본, native plugin(iOS/Android) 자동 가입 요청, BLE 핸드셰이크 | E21: ✅ | F21: 1회 연결만, 로밍 미지원
A22: WiFi 로밍 (B 풀스코프) | B22: Phase 1 | C22: P14~P19 | D22: wifi_profiles 확장 + beacon_wifi·units·grant·devices + admin/provider 등록 + mobile 클라이언트 + .mobileconfig 다건 + managed/units (flag) | E22: ⬜ | F22: 6월 말~7월 중
A23: 비콘 (인벤토리/claim/모니터) | B23: 이전 완료 | C23: PR #37, #38 | D23: admin 인벤토리 CSV 입고, provider claim, 배터리 모니터링, 펌웨어 표시 | E23: ✅
A24: 비콘 | B24: Phase 1 | C24: P15 (병합) | D24: beacons.role(wifi/cashier) 추가 + admin·provider UI | E24: ⬜
A25: i18n (12언어) | B25: 이전 완료 | C25: BE translations API + admin CRUD | D25: 백엔드 translations 테이블, DeepL 통합, 12개 supportedLocales, admin CRUD | E25: ✅
A26: i18n | B26: Phase 1 | C26: P2 | D26: mobile I18nService DB 통일 + 전 화면 t() 전환 + ko 시드 550 + DeepL 일괄번역 스크립트 | E26: ✅ | F26: 11개 언어 번역 = DeepL 키 확보 후 batch 실행
A27: i18n | B27: 남은 | C27: DeepL 번역 batch | D27: translations DB의 ko 키 → 11개 언어 자동 번역(약 22 × 549건) | E27: ⬜ | F27: DeepL API 키 활성화 후
A28: 정책/약관 | B28: 이전 완료 | C28: 8종 KIND 등록 | D28: terms, privacy, location, marketing, push, camera, storage, third_party, age14 DB 등록 | E28: ✅
A29: 정책/약관 | B29: Phase 1 | C29: P13 | D29: 환불·청소년·쿠키 정책 3종 BE/admin/노출 추가 + policy_view 언어 정합 | E29: ⬜
A30: 디자인 시스템 | B30: 이전 완료 | C30: 3콘솔 디자인 정합 | D30: mobile dark + 보라, provider-web dark + 녹색, admin-web dark + 블루 — 3콘솔 디자인 토큰 통일 | E30: ✅
A31: 디자인 시스템 | B31: Phase 1 | C31: P1·P3 | D31: mobile 테마 단일화 + 시스템 폰트 + Pw* 위젯 / 웹 alert·confirm 33곳 → 공용 모달 | E31: ✅
A32: 슈퍼어드민 (admin-web) | B32: 이전 완료 | C32: PR #36~#39, #142 | D32: Login + Dashboard + Beacons + Approvals + Battery + Announcements + Payments + Subscriptions + Policies + Reports + Translations + Audit | E32: ✅
A33: 슈퍼어드민 | B33: Phase 1 | C33: P11·P20 | D33: Dashboard 가짜데이터 제거 + StaffMonitor·CouponStats placeholder 해소 + app-versions UI(BE 완성) | E33: ⬜
A34: 직원 관리 | B34: 이전 완료 | C34: 백엔드 staff API | D34: 직원 초대/권한/관리 백엔드 | E34: ✅
A35: 직원 관리 | B35: Phase 1 | C35: P11 | D35: provider StaffManagement 실연동 + admin StaffMonitor 실연동 | E35: ⬜
A36: 심의 직격 (mobile) | B36: Phase 1 | C36: P12 | D36: consent placeholder 제거 + 동의 로드 실패 복구 + settings dev 정보 제거 + 앱 버전 동적화 | E36: ⬜ | F36: 심의 reject 방지
A37: 심의 메타 자산 | B37: Phase 1 | C37: P21 | D37: PrivacyInfo.xcprivacy + Bundle ID 확정 + Android Photo Picker + 계정삭제 웹 URL | E37: ⬜ | F37: iOS/Android 심사 필수
A38: OCR 허위 제거 | B38: Phase 1 | C38: P6 | D38: WifiSettings·ServiceRequest runOcrMock 제거 → 정직한 수동입력 UI | E38: ✅ | F38: 심의 reject 방지
A39: 회사 정보 (footer) | B39: Phase 1 | C39: P5 (포함) | D39: Settings 푸터 → PwFooter (CompanyInfoService → 트리거소프트 실 법인정보) | E39: ✅ | F39: 법인 등기 완료
A40: 운영 인프라 | B40: 이전 완료 | C40: PR #35, #41, #51 | D40: SECRET_KEY/AES_KEY ENV + CORS 화이트리스트 + rate-limit + gunicorn/wsgi + Sentry + PostgreSQL 어댑터 | E40: ✅ | F40: 실 호스팅은 외부 서비스 활성화 후
A41: Phase 2~4 테스트 | B41: 남은 | C41: W7 테스트 시드 | D41: 6 페르소나(외국인/한국인/소규모/중대형/직원/슈퍼어드민) 테스트 데이터 시드 + 시나리오 검증 | E41: ⬜ | F41: 7월 중순~하순
...

Sheet Phase 1 PR 체크리스트
A1: PR | B1: 분류 | C1: 도메인 | D1: 콘솔/영역 | E1: 내용 요약 | F1: 상태 | G1: 진척율 | H1: 담당 | I1: 시작일 | J1: 목표일 | K1: 완료일 | L1: 검증 시나리오 / 메모
A2: P1 | B2: 인프라 | C2: mobile 디자인 기반 | D2: mobile | E2: 테마 단일화 + 시스템 폰트 + Pw* 위젯 4종 | F2: ✅ | G2: =IF(F2="✅",1,IF(F2="🔄",0.5,IF(F2="◑",0.7,IF(F2="🔎",0.9,0)))) | H2: 2026-05-21 | I2: 2026-05-22 | J2: 2026-05-23
A3: P2 | B3: 인프라 | C3: mobile i18n | D3: mobile·BE | E3: 12언어 단일화 + 전 화면 t() + ko 시드 550 + DeepL 스크립트 | F3: ✅ | G3: =IF(F3="✅",1,IF(F3="🔄",0.5,IF(F3="◑",0.7,IF(F3="🔎",0.9,0)))) | H3: 2026-05-21 | I3: 2026-05-22 | J3: 2026-05-23
A4: P3 | B4: 인프라 | C4: 웹 디자인 시스템 | D4: provider·admin | E4: alert/confirm 33곳 → useDialog 공용 모달 + 색 토큰 | F4: ✅ | G4: =IF(F4="✅",1,IF(F4="🔄",0.5,IF(F4="◑",0.7,IF(F4="🔎",0.9,0)))) | H4: 2026-05-21 | I4: 2026-05-22 | J4: 2026-05-23
A5: P4 | B5: Critical | C5: 인증 우회 제거 | D5: provider·admin·BE | E5: DEV_AUTO_LOGIN env 게이트 + 실 로그인폼 + /forgot-password 정식 | F5: ✅ | G5: =IF(F5="✅",1,IF(F5="🔄",0.5,IF(F5="◑",0.7,IF(F5="🔎",0.9,0)))) | H5: 2026-05-23 | I5: 2026-05-23 | J5: 2026-05-23 | K5: ⚠ app.py 재시작 필요
A6: P5 | B6: Critical | C6: 매장·회사정보 실연동 | D6: provider | E6: StoreInfo 실연동 + PwFooter + dead code 정리 | F6: ✅ | G6: =IF(F6="✅",1,IF(F6="🔄",0.5,IF(F6="◑",0.7,IF(F6="🔎",0.9,0)))) | H6: 2026-05-23 | I6: 2026-05-23 | J6: 2026-05-23
A7: P6 | B7: Critical | C7: OCR 허위 제거 | D7: provider | E7: 가짜 OCR 자동입력 제거 → 정직한 수동입력 UI | F7: ✅ | G7: =IF(F7="✅",1,IF(F7="🔄",0.5,IF(F7="◑",0.7,IF(F7="🔎",0.9,0)))) | H7: 2026-05-23 | I7: 2026-05-23 | J7: 2026-05-23
A8: P7 | B8: Critical | C8: 결제·구독 실연동 | D8: provider·admin | E8: 카드 localStorage 제거(PCI) + BillingService + 실연동 | F8: ✅ | G8: =IF(F8="✅",1,IF(F8="🔄",0.5,IF(F8="◑",0.7,IF(F8="🔎",0.9,0)))) | H8: 2026-05-23 | I8: 2026-05-23 | J8: 2026-05-23
A9: P8 | B9: Critical | C9: 채팅 도메인 | D9: mobile·provider·admin·BE | E9: provider CustomerChat + admin ChatMonitor + BE 신고 API + mobile SSE 재연결 | F9: ◑ | G9: =IF(F9="✅",1,IF(F9="🔄",0.5,IF(F9="◑",0.7,IF(F9="🔎",0.9,0)))) | H9: 2026-05-23 | I9: 2026-05-23 | J9: 2026-05-23 | K9: 번역=P8b 분리, ⚠ app.py 재시작
A10: P8b | B10: Critical | C10: 채팅 자동 번역 | D10: mobile·provider·BE | E10: 번역 캐시 스키마 + 뷰어별 언어 + translator↔chat 연결 | F10: ⬜ | G10: =IF(F10="✅",1,IF(F10="🔄",0.5,IF(F10="◑",0.7,IF(F10="🔎",0.9,0)))) | I10: 키 확보 후 | K10: Google/DeepL 키 확보 후
A11: P9 | B11: Critical | C11: 쿠폰·스탬프 실연동 | D11: mobile·provider | E11: Coupons·Stamps mock→실연동 | F11: ⬜ | G11: =IF(F11="✅",1,IF(F11="🔄",0.5,IF(F11="◑",0.7,IF(F11="🔎",0.9,0)))) | I11: 2026-06-중
A12: P10 | B12: Critical | C12: 알림 도메인 | D12: mobile·provider·admin | E12: Notifications 실연동 + mobile 라우팅 | F12: ⬜ | G12: =IF(F12="✅",1,IF(F12="🔄",0.5,IF(F12="◑",0.7,IF(F12="🔎",0.9,0)))) | I12: 2026-06-중
A13: P11 | B13: Critical | C13: 대시보드·직원 | D13: provider·admin·BE | E13: Dashboard·StaffManagement 실연동 | F13: ⬜ | G13: =IF(F13="✅",1,IF(F13="🔄",0.5,IF(F13="◑",0.7,IF(F13="🔎",0.9,0)))) | I13: 2026-06-중
A14: P12 | B14: Critical | C14: mobile 심의 직격 | D14: mobile·BE | E14: consent placeholder + dev 정보 제거 + 앱 버전 동적화 | F14: ⬜ | G14: =IF(F14="✅",1,IF(F14="🔄",0.5,IF(F14="◑",0.7,IF(F14="🔎",0.9,0)))) | I14: 2026-06-중
A15: P13 | B15: Critical | C15: 약관 3종 | D15: mobile·provider·admin·BE | E15: 환불·청소년·쿠키 정책 | F15: ⬜ | G15: =IF(F15="✅",1,IF(F15="🔄",0.5,IF(F15="◑",0.7,IF(F15="🔎",0.9,0)))) | I15: 2026-06-중
A16: P14 | B16: WiFi 로밍 B | C16: WiFi 데이터 모델 | D16: BE | E16: wifi_profiles 확장 + beacon_wifi·units·grant·devices | F16: ⬜ | G16: =IF(F16="✅",1,IF(F16="🔄",0.5,IF(F16="◑",0.7,IF(F16="🔎",0.9,0)))) | I16: 2026-06-말~7월초
A17: P15 | B17: WiFi 로밍 B | C17: WiFi 등록·연동 | D17: provider·admin·BE | E17: handshake 묶음 + admin WiFi 등록 + provider WifiSettings | F17: ⬜ | G17: =IF(F17="✅",1,IF(F17="🔄",0.5,IF(F17="◑",0.7,IF(F17="🔎",0.9,0)))) | I17: 2026-07-초
A18: P16 | B18: WiFi 로밍 B | C18: mobile WiFi 클라이언트 | D18: mobile | E18: 비콘→WiFi 묶음 fetch + BSSID 검증 | F18: ⬜ | G18: =IF(F18="✅",1,IF(F18="🔄",0.5,IF(F18="◑",0.7,IF(F18="🔎",0.9,0)))) | I18: 2026-07-초
A19: P17 | B19: WiFi 로밍 B | C19: .mobileconfig 다건 | D19: BE·mobile·iOS | E19: .mobileconfig 생성·다건 설치 | F19: ⬜ | G19: =IF(F19="✅",1,IF(F19="🔄",0.5,IF(F19="◑",0.7,IF(F19="🔎",0.9,0)))) | I19: 2026-07-중 | K19: 서명은 인증서 후
A20: P18 | B20: WiFi 로밍 B | C20: credential_mode managed | D20: BE·provider·mobile | E20: 비번 교체 리마인드 + 인가 손님 자동 전파 | F20: ⬜ | G20: =IF(F20="✅",1,IF(F20="🔄",0.5,IF(F20="◑",0.7,IF(F20="🔎",0.9,0)))) | I20: 2026-07-중 | K20: v1 flag 비공개
A21: P19 | B21: WiFi 로밍 B | C21: units/grant 관리 | D21: admin·provider·BE | E21: 호실·자리 시간제 권한 UI | F21: ⬜ | G21: =IF(F21="✅",1,IF(F21="🔄",0.5,IF(F21="◑",0.7,IF(F21="🔎",0.9,0)))) | I21: 2026-07-중 | K21: v1 flag 비공개
A22: P20 | B22: 심의 마무리 | C22: 앱 버전관리 | D22: admin·mobile | E22: admin app-versions UI + mobile OS 최소버전 게이트 | F22: ⬜ | G22: =IF(F22="✅",1,IF(F22="🔄",0.5,IF(F22="◑",0.7,IF(F22="🔎",0.9,0)))) | I22: 2026-07-중
A23: P21 | B23: 심의 마무리 | C23: 심의 메타 자산 | D23: mobile·iOS | E23: PrivacyInfo.xcprivacy + Bundle ID + Photo Picker | F23: ⬜ | G23: =IF(F23="✅",1,IF(F23="🔄",0.5,IF(F23="◑",0.7,IF(F23="🔎",0.9,0)))) | I23: 2026-07-중
A24: P22 | B24: 회원 QR 운영 | C24: 쿠폰·스탬프 회원 QR | D24: mobile·provider·BE | E24: 회원 QR + provider 스캔/코드입력 + 친구초대 QR | F24: ⬜ | G24: =IF(F24="✅",1,IF(F24="🔄",0.5,IF(F24="◑",0.7,IF(F24="🔎",0.9,0)))) | I24: 2026-07-초~중 | K24: P9 이후 병행

Sheet 단계별 일정
A1: 단계 | B1: 내용 | C1: 예상 기간 | D1: 누적 | E1: 비고
A2: 이전 작업 (~Phase 0) | B2: PR #1~#51 + 디자인 통합 + 51 PR 머지 | C2: ~수개월 | D2: 2026-05-21 | E2: 완료 — 코드 측면 출시 직전
A3: Phase 0 전수 감사 | B3: 갭 리스트 14 Critical + High 발굴 | C3: ~1일 | D3: 2026-05-21 | E3: 완료
A4: Phase 1 인프라 | B4: P1~P3 | C4: ~4일 | D4: 2026-05-22 | E4: 완료
A5: Phase 1 Critical | B5: P4~P13 (10 PR) | C5: ~2주 | D5: 2026-06-중 | E5: P4~P8 완료
A6: Phase 1 WiFi 로밍 B | B6: P14~P19 (6 PR) | C6: ~2.5~3주 | D6: 2026-07-초~중 | E6: feature flag
A7: Phase 1 회원 QR | B7: P22 (P9 이후 병행) | C7: ~1주 | D7: 2026-07-초~중
A8: Phase 1 심의 마무리 | B8: P20~P21 | C8: ~3일 | D8: 2026-07-중
A9: Phase 2~4 테스트·시드 | B9: 6 페르소나 + 시나리오 검증 | C9: ~1.5주 | D9: 2026-07-중~하순
A10: Phase 5 제출 준비 | B10: 빌드 + 스토어 메타데이터 | C10: 며칠 | D10: 2026-07-하순
A11: 출시 | B11: 앱스토어/Play 공개 | C11: — | D11: 2026-07-하순~8월 초
A12: 외부 서비스 신청 시작 | B12: 법인카드 수취 후 일괄 신청 | C12: ~1주 (심사 1~2주) | D12: 2026-06-02 주 | E12: 카카오·솔라피·토스 심사 병행
