Workbook

Sheet Cover
B2: PathWave 페르소나 통합 테스트 시나리오
B3: 작성일: 2026-05-26 · IA 와 같이 관리 (build_test_scenarios.py)
B5: 페르소나 14명
B6: P1 | C6: 외국인 관광객 · mobile (iOS) / 일본어 (lang=ja) · i18n en fallback, 메뉴 자동번역, 채팅 자동번역
B7: P2 | C7: 한국인 일반 사용자 · mobile (Android) / 한국어 · 표준 가입, BLE 스캔, 스탬프, 쿠폰, 1:1 채팅
B8: P3 | C8: 소규모 매장 사장 (1인) · provider-web (Chrome/Safari) · 가입 + 운영자 승인 + 1계정 1매장 + 비콘 claim + WiFi 등록
B9: P4 | C9: 중대형 매장 사장 · provider-web · P3 + 직원 초대 + 권한 분리 + 정산 + 통계
B10: P5 | C10: 매장 직원 · provider-web (초대 가입) · 초대 코드 가입 + 사장 권한 일부 + QR 스캔
B11: P6 | C11: 슈퍼어드민 · admin-web (Chrome) · 비콘 CSV / 매장 승인 / 약관 / 신고 처리 / 비용 모니터
B12: P7 | C12: 친구 초대 발급자 · mobile (user → user) · 초대 코드 발급 + 외부 채널 공유 + 친구 가입 확인
B13: P8 | C13: 친구 초대 가입 사용자 · mobile (invitation_code) · 코드 입력 → 가입 → 초대자와 연결
B14: P9 | C14: 만 14세 미만 + 보호자 · mobile (parent flow) · birth_year < 14 → 보호자 동의 → 가입 완료
B15: P10 | C15: 소셜 로그인 사용자 · mobile (Kakao/Naver/Apple/Google) · OAuth → JWT 발급 → 약관 동의 흐름
B16: P11 | C16: 비밀번호 재설정 · mobile / provider-web · forgot-password → 이메일 링크 → reset-password
B17: P12 | C17: 푸시 토큰 등록 · mobile (FCM/APNS) · 권한 동의 → 토큰 등록 → 매장 공지 수신
... B19: P14 | C19: 알림 발송 승인 흐름 · provider → admin → 사용자 · 사장 발송 요청 → 슈퍼어드민 승인/거절 → dispatch
B22: 결과 기호
B24: ● | C24: 디바이스/브라우저 대상 — 테스트 수행
B25: (공백) | C25: 디바이스/브라우저 비대상
B26: Pass | C26: 기대결과 일치
B27: Fail | C27: 기대결과 불일치 — 비고에 사유 + GitHub Issue 링크
B28: Skip | C28: 환경 미준비 (예: 실 비콘 / 실 키) — 다음 라운드
B31: 컬럼 의미
B33: 화면ID | C33: IA xlsx 의 화면 ID (U-001 / P-001 / A-001) 와 1:1 매칭. 신규 화면 추가 시 IA 동시 갱신.
B34: 구분 | C34: USER (mobile) / Provider (provider-web) / Admin (admin-web)
B35: 메뉴/화면 | C35: 입력/선택/저장/조회 액션이 일어나는 정확한 위치
B36: 가이드/진입 | C36: 어떻게 그 화면에 진입하는지 (홈에서 N탭 등)
B37: 테스트 데이터 | C37: 계정/ID/세부 입력값 — R2 단계에서 테스트 계정 시드와 일치 시킴
B38: 기대결과 | C38: 코드 동작 기준 — API status/DB 변화/UI 표시
B39: 디바이스 4종 | C39: Galaxy S24 / iPhone 16 Pro / Safari / Chrome — ● 표시된 곳만 실행
B40: Pass 여부 | C40: 테스터 확인 후 채우는 컬럼 — Pass / Fail / Skip
B41: 비고 | C41: 결합내용 / 페르소나 ID / 디펜던시 / 이슈 링크
B42: 테스터 | C42: 확인자 이름 (개발팀 / QA / 사용자)
B45: 지속 관리 가이드
B47: 1. 재생성 | C47: /Users/m5pro16/Desktop/pathwave/venv/bin/python docs/build_test_scenarios.py
B48: 2. 신규 시나리오 | C48: docs/build_test_scenarios.py 의 ROWS 에 add(...) 추가 후 재생성
B49: 3. IA 동기화 | C49: 화면ID 가 IA xlsx 와 어긋나면 즉시 갱신. 신규 IA 행 추가 시 시나리오 후보 검토
B50: 4. R2 테스터 분배 | C50: 페르소나별 시트(Persona-Index) 보고 테스터에 분배. Pass 컬럼은 실제 테스터가 직접 입력
B51: 5. Fail 처리 | C51: 비고 컬럼에 GitHub Issue 링크 + 재시도 일정. 재시도 후 다시 Pass 처리
B52: 6. 결과 보고 | C52: Persona-Index 시트의 Pass / Fail / Skip 카운트로 진행률 파악

Sheet Scenarios
A1: No | B1: 화면ID | C1: 화면명 | D1: 구분 | E1: 테스트 수행 메뉴/화면 (입력/선택/저장/조회) | F1: 가이드/진입 | G1: 테스트 수행 내용 | H1: 테스트 데이터 (상품번호/회원 아이디) | I1: 테스트 결과 화면/메뉴 (조회/확인) | J1: 테스트 기대결과 | K1: Galaxy S24 | L1: iPhone 16 Pro | M1: Safari | N1: Chrome | O1: 테스트결과 (Pass여부) | P1: 비고 (결합내용 등) | Q1: 테스터 (기대결과 확인)
A2: 1 | B2: U-001 | C2: 스플래시 | D2: USER | E2: 앱 첫 실행 — 디바이스 lang=ja | F2: 앱 아이콘 터치 | G2: OS 언어 ja 감지 → /api/i18n/ja 응답 (en fallback) → 로그인/온보딩 화면 | H2: 디바이스 ja 설정 | I2: 로그인 화면 (영문 UI) | J2: UI 텍스트가 영문 fallback 으로 표시. 한국어 잔존 X | K2: ● | L2: ● | P2: P1:
A3: 2 | B3: U-003 | C3: 회원가입 | D3: USER | E3: 이메일 + 코드 + 약관 | F3: 로그인 화면 → "Sign up" | G3: 이메일 입력 → 코드 발송 → 코드 검증 → 비번 + 약관 동의 | H3: jp_tour@pathwave.test | I3: 약관 모달 (en 본문) | J3: /api/policies?sub_type=user&lang=ja → en fallback. terms_user/privacy_user 필수 | K3: ● | L3: ● | P3: P1:
A4: 3 | B4: U-007 | C4: WiFi 자동 연결 | D4: USER | E4: 매장 입장 후 BLE 감지 | F4: 매장 입장 (비콘 신호 도달) | G4: BLE 스캔 → handshake → .mobileconfig 자동 설치 (iOS) → WiFi 연결 | H4: 매장 비콘 1개 (mock 가능) | I4: WiFi 연결됨 알림 | J4: POST /api/beacon/handshake → 200 + wifi profile. 무중단 핸드오프는 P16-b (out of scope v1) | K4: ● | L4: ● | P4: P1:
A5: 4 | B5: U-008 | C5: 매장 상세 — 메뉴 자동 번역 | D5: USER | E5: 매장 상세 안 "Menu" 섹션 | F5: 매장 진입 (BLE 또는 검색) | G5: 한국어 메뉴 OCR 결과 → 일본어 자동 번역 표시 (가격은 KRW 원본) | H5: facility_id 매장 메뉴 등록됨 | I5: 메뉴 항목 ja 표시 + 가격 ₩ | J5: GET /api/facilities/{fid}/menu?lang=ja → source=translated. price 환산 X (KRW 그대로) | K5: ● | L5: ● | P5: P1:
A6: 5 | B6: U-009 | C6: 채팅 자동 번역 | D6: USER | E6: 매장과 1:1 채팅 | F6: 매장 상세 → "Chat" | G6: 일본어 입력 → 사장 화면에 ko 번역+원문. 사장 ko 답변 → 사용자에 ja 번역+원문 | H6: jp_tour ↔ shop1 | I6: 양방향 채팅 자동 번역 | J6: tests/test_chat_translation.py 참조. DeepL stub 또는 실키 | K6: ● | L6: ● | P6: P1:
A7: 6 | B7: U-013 | C7: 푸시 알림 수신 (en) | D7: USER | E7: 매장 공지 수신 | F7: 매장 공지 발송 후 | G7: FCM 푸시 본문 en (lang fallback). 한국어 단말은 ko 동시 발송 확인 | H7: 매장 공지 1건 | I7: 푸시 알림 (en 본문) | J7: P8c 푸시 번역 회귀 (test_push_translation) | K7: ● | L7: ● | P7: P1:
A8: 7 | B8: U-003 | C8: 회원가입 ko | D8: USER | E8: 이메일 + 코드 + 약관 ko | F8: 로그인 → "회원가입" | G8: 이메일 → 코드 발송 → 코드 검증 → 비번 + 약관 한국어 본문 동의 | H8: kr_user@pathwave.test | I8: 약관 모달 (ko 본문) | J8: terms_user/privacy_user 한국어. 가입 200 + access_token | K8: ● | L8: ● | P8: P2:
A9: 8 | B9: U-006 | C9: 홈 — 근처 매장 | D9: USER | E9: 홈 화면 + 위치 권한 허용 | F9: 로그인 후 홈 | G9: 근처 매장 (위치 기반) / 즐겨찾기 / 최근 방문 | H9: 서울 강남구 위치 | I9: 매장 카드 N개 | J9: GET /api/search/facilities?lat=..&lon=.. | K9: ● | L9: ● | P9: P2:
A10: 9 | B10: U-010 | C10: 스탬프 적립 | D10: USER | E10: 매장 직원이 QR 스캔 | F10: 매장 방문 후 QR 발급 | G10: 쿠폰 QR 표시 → 직원 스캔 → 스탬프 적립 | H10: kr_user QR + 매장 직원 | I10: 스탬프 카드 +1 | J10: 매장 스탬프 정책 적용. 1일 1회 등 | K10: ● | L10: ● | P10: P2:
A11: 10 | B11: U-011 | C11: 쿠폰 사용 | D11: USER | E11: 내 쿠폰 → 사용 | F11: 마이 → 쿠폰 | G11: 쿠폰 선택 → QR 표시 → 직원 스캔 → 사용 처리 | H11: 발급된 쿠폰 1건 | I11: 쿠폰 used=true | J11: POST /api/coupons/{id}/use. 만료/중복 차단 확인 | K11: ● | L11: ● | P11: P2:
A12: 11 | B12: U-016 | C12: 계정 삭제 | D12: USER | E12: 설정 → 계정 삭제 | F12: 마이 → 설정 | G12: "계정 삭제" → 비번 재확인 → 사유 → 확인 | H12: kr_user / 본인 비번 | I12: 즉시 로그아웃 | J12: DELETE /api/auth/me. 이메일 anonymize + push 토큰 삭제 | K12: ● | L12: ● | P12: P2:
A13: 12 | B13: P-001 | C13: 로그인 | D13: Provider | E13: 로그인 화면 | F13: provider-web /login | G13: 이메일 + 비번 입력 → 로그인 | H13: shop1@pathwave.test / Shop1234! | I13: 대시보드 진입 | J13: 미인증 매장은 pending 화면. verified 매장은 dashboard | M13: ● | N13: ● | P13: P3:
A14: 13 | B14: P-002 | C14: 가입 | D14: Provider | E14: 회원가입 | F14: /signup | G14: 이메일/사업자번호/약관(terms_facility/privacy_facility) → 201 pending | H14: 신규 사업자번호 | I14: "승인 대기" 안내 | J14: POST /api/facility/register. status=pending → admin verify 대기 | M14: ● | N14: ● | P14: P3:
A15: 14 | B15: P-004 | C15: 매장 정보 수정 | D15: Provider | E15: /dashboard/store | F15: 대시보드 → 매장 정보 | G15: 매장명/주소/사진/운영시간 변경 → 저장 | H15: fid 1 | I15: 저장 토스트 | J15: PATCH /api/facilities/{fid} | M15: ● | N15: ● | P15: P3:
A16: 15 | B16: P-005 | C16: 비콘 claim | D16: Provider | E16: /dashboard/store → 비콘 | F16: admin 이 입고한 SN 입력 | G16: SN 입력 + role(wifi/cashier) 선택 → claim | H16: SN: PW-BCN-001 (admin 입고) | I16: 비콘 active 표시 | J16: POST /api/facilities/{fid}/claim-beacon | M16: ● | N16: ● | P16: P3:
A17: 16 | B17: P-009 | C17: WiFi 프로파일 등록 | D17: Provider | E17: /dashboard/wifi | F17: 대시보드 → 와이파이 | G17: SSID + 비번 입력 → 저장 (AES-256-GCM 암호화 저장) | H17: SSID/비번 | I17: WiFi 목록 +1 | J17: POST /api/beacon/wifi. DB password 평문 X 검증 | M17: ● | N17: ● | P17: P3:
A18: 17 | B18: P-014 | C18: 메뉴 OCR 업로드 | D18: Provider | E18: /dashboard/menu | F18: 메뉴 관리 → 사진 업로드 | G18: 메뉴판 이미지 (jpg/png) 업로드 → OCR 결과 인라인 표 확인 + 수정 | H18: 메뉴판 이미지 | I18: 메뉴 항목 표 (KRW 가격) | J18: POST /api/facilities/{fid}/menu/upload. 가격 KRW 강제 | M18: ● | N18: ● | P18: P3:
A19: 18 | B19: P-015 | C19: 매장 다국어 관리 | D19: Provider | E19: /dashboard/store-translations | F19: 대시보드 → 매장 다국어 | G19: 영어 탭 → 매장명/주소/설명 입력 → 저장. 또는 "자동 번역" | H19: fid 1, lang=en | I19: 저장 + en 탭 ● 표시 | J19: PUT /api/facilities/{fid}/translations/en | M19: ● | N19: ● | P19: P3:
A20: 19 | B20: P-012 | C20: 구독 결제 | D20: Provider | E20: /dashboard/payments | F20: 결제 관리 | G20: 플랜 선택 → 카드 등록 → 토스 결제 | H20: 토스 sandbox | I20: subscriptions row | J20: POST /api/billing/subscriptions. R2 (실키) 단계 | M20: ● | N20: ● | P20: P3:
A21: 20 | B21: P-019 | C21: 직원 초대 코드 발급 | D21: Provider | E21: /dashboard/staff → "초대" | F21: 직원 관리 | G21: 이메일 + role(staff/admin) 입력 → 초대 발급 | H21: staff1@pathwave.test | I21: 초대 목록 +1, 토큰 발급 | J21: POST /api/staff/invite. invite_token API 응답 비노출 (DB+이메일) | M21: ● | N21: ● | P21: P4:
A22: 21 | B22: P-019 | C22: 직원 해지 | D22: Provider | E22: /dashboard/staff → "해지" | F22: 직원 카드 → 해지 | G22: pending 초대 revoke 또는 active staff 해지 | H22: invitation_id 1 | I22: 직원 상태 revoked | J22: DELETE /api/staff/{iid} | M22: ● | N22: ● | P22: P4:
A23: 22 | B23: U-003 | C23: 직원 가입 (초대 코드) | D23: Provider | E23: /signup?code=... | F23: 이메일 받은 초대 링크 | G23: 코드 검증 → 비번 + 약관 동의 → 직원 계정 생성 | H23: invite_token | I23: 직원 로그인 가능 | J23: POST /api/staff/accept. terms_facility/privacy_facility 필수 | M23: ● | N23: ● | P23: P5:
A24: 23 | B24: P-001 | C24: 직원 로그인 | D24: Provider | E24: /login (staff) | F24: 이메일 + 비번 | G24: 직원 토큰 발급 + 대시보드 진입 (권한 제한) | H24: staff1@pathwave.test | I24: 대시보드 (권한 제한) | J24: POST /api/staff/login | M24: ● | N24: ● | P24: P5:
... A33: 32 | B33: A-026 | C33: 글로벌 임계점 알림 모달 | D33: Admin | E33: 80%/100% 도달 시 자동 표시 | F33: admin-web 진입 | G33: 알림 팝업 모달 + "확인 (N시간 후 재알림)" | H33: 비용 임계점 도달 | I33: snooze 24h (80%) / 2h (100%) | J33: GET /api/admin/critical-alerts. POST /alerts/{id}/dismiss | M33: ● | N33: ● | P33: P6:
A34: 33 | B34: U-015 | C34: 친구 초대 코드 발급 | D34: USER | E34: 홈 → "친구 초대" | F34: 마이 또는 홈 → 초대 | G34: 초대 코드 발급 → SMS/이메일 공유 옵션 | H34: kr_user | I34: 코드 + 공유 시트 | J34: POST /api/invitations | K34: ● | L34: ● | P34: P7:
A35: 34 | B35: U-015 | C35: 내 초대 이력 | D35: USER | E35: 내가 보낸 초대 | F35: 초대 화면 | G35: 내 발급 코드 목록 + 가입 여부 | H35: 초대 N건 | I35: 코드/상태 표 | J35: GET /api/invitations | K35: ● | L35: ● | P35: P7:
A36: 35 | B36: U-003 | C36: 초대 코드 입력 가입 | D36: USER | E36: 회원가입 화면 → 초대 코드 | F36: register_screen | G36: invitation_code 입력 → 가입 | H36: code=ABCD1234 | I36: 가입 완료 + 초대자 연결 | J36: POST /api/auth/register with invitation_code. consume_invitation | K36: ● | L36: ● | P36: P8:
A37: 36 | B37: U-015 | C37: 초대자 보상 확인 | D37: USER | E37: 내 초대 이력 | F37: P7 초대자가 확인 | G37: 친구 가입됨 표시 | H37: 초대 1건 used | I37: "가입 완료" 배지 | J37: 초대 보상 정책은 v1 미정 — 별도 | K37: ● | L37: ● | P37: P8:
A38: 37 | B38: U-003 | C38: 14세 미만 가입 거부 | D38: USER | E38: 회원가입 — birth_year=2020 | F38: register_screen | G38: birth_year 2020 입력 → 가입 시도 | H38: birth_year=2020 | I38: 400 + "보호자 동의 필요" | J38: register validate — age_group=minor / parent invite 안내 | K38: ● | L38: ● | P38: P9:
A39: 38 | B39: U-018 | C39: 보호자 초대 발급 | D39: USER | E39: 보호자 이메일 입력 | F39: parent_invite_screen | G39: 보호자 이메일 → 동의 메일 발송 | H39: parent@email | I39: 동의 대기 안내 | J39: POST /api/invitations/parent | K39: ● | L39: ● | P39: P9:
A40: 39 | B40: U-018 | C40: 보호자 동의 → 가입 완료 | D40: USER | E40: 보호자가 메일 링크 클릭 | F40: 동의 페이지 | G40: 동의 → 자녀 가입 자동 완료 | H40: parent token | I40: 자녀 계정 active | J40: GET /api/invitations/{code} + 가입 완료 트리거 | K40: ● | L40: ● | P40: P9:
A41: 40 | B41: U-002 | C41: 카카오 로그인 | D41: USER | E41: 로그인 화면 → "카카오로 시작" | F41: login_screen | G41: Kakao OAuth → /api/auth/social | H41: Kakao test acc | I41: 가입 + JWT 발급 | J41: POST /api/auth/social provider=kakao. 비번 없음 | K41: ● | L41: ● | P41: P10:
A42: 41 | B42: U-002 | C42: 구글 로그인 | D42: USER | E42: 로그인 화면 → "구글로 시작" | F42: login_screen | G42: Google OAuth → /api/auth/social | H42: Google test acc | I42: 가입 + JWT 발급 | J42: POST /api/auth/social provider=google | K42: ● | L42: ● | P42: P10:
A43: 42 | B43: U-002 | C43: 애플 로그인 | D43: USER | E43: 로그인 화면 → "Apple 로 시작" | F43: login_screen (iOS 만) | G43: Apple Sign In → /api/auth/social | H43: Apple test acc | I43: 가입 + JWT 발급 | J43: provider=apple. iOS 만 노출 | L43: ● | P43: P10:
A44: 43 | B44: U-016 | C44: 소셜 사용자 계정 삭제 | D44: USER | E44: 설정 → 계정 삭제 | F44: 마이 → 설정 | G44: 비번 입력 단계 skip (소셜은 비번 없음) | H44: kakao 사용자 | I44: 즉시 삭제 | J44: DELETE /api/auth/me. provider=email 만 비번 재확인 | K44: ● | L44: ● | P44: P10:
A45: 44 | B45: U-019 | C45: 비밀번호 찾기 요청 | D45: USER | E45: 로그인 화면 → "비밀번호 찾기" | F45: forgot_password_screen | G45: 이메일 입력 → 재설정 링크 메일 발송 | H45: kr_user@pathwave.test | I45: 메일 발송 안내 | J45: POST /api/auth/forgot-password. rate limit 3/min | K45: ● | L45: ● | P45: P11:
A46: 45 | B46: U-019 | C46: 재설정 — 새 비번 등록 | D46: USER | E46: 메일 링크 클릭 | F46: 재설정 페이지 (앱 또는 web) | G46: 새 비번 + 확인 → 저장 | H46: reset_token | I46: 재설정 완료, 새 비번으로 로그인 | J46: POST /api/auth/reset-password. 토큰 만료 24h | K46: ● | L46: ● | P46: P11:
A47: 46 | B47: U-020 | C47: 푸시 권한 동의 | D47: USER | E47: 앱 첫 실행 — OS 권한 다이얼로그 | F47: splash_screen | G47: OS 권한 다이얼로그 → 허용 | H47: 신규 사용자 | I47: 권한 허용 + FCM 토큰 발급 | J47: POST /api/push (token, platform=fcm|apns, language) | K47: ● | L47: ● | P47: P12:
A48: 47 | B48: U-013 | C48: 매장 공지 푸시 수신 | D48: USER | E48: 백그라운드 상태 | F48: 매장 공지 발송 | G48: 잠금 화면에 푸시 알림 노출 | H48: 매장 공지 1건 | I48: 알림 표시 (lang 별 본문) | J48: 디바이스 lang ko 사용자는 ko, ja 사용자는 en | K48: ● | L48: ● | P48: P12:
...

Sheet Persona-Index
A1: ID | B1: 페르소나 | C1: 시나리오 수 | D1: Pass | E1: Fail | F1: Skip | G1: 미실행
A2: P1 | B2: 외국인 관광객 | C2: 6 | D2: =COUNTIFS(Scenarios!P:P,"P1:*",Scenarios!O:O,"Pass") | E2: =COUNTIFS(Scenarios!P:P,"P1:*",Scenarios!O:O,"Fail") | F2: =COUNTIFS(Scenarios!P:P,"P1:*",Scenarios!O:O,"Skip") | G2: =C2-D2-E2-F2
A3: P2 | B3: 한국인 일반 사용자 | C3: 5 | D3: =COUNTIFS(Scenarios!P:P,"P2:*",Scenarios!O:O,"Pass") | E3: =COUNTIFS(Scenarios!P:P,"P2:*",Scenarios!O:O,"Fail") | F3: =COUNTIFS(Scenarios!P:P,"P2:*",Scenarios!O:O,"Skip") | G3: =C3-D3-E3-F3
A4: P3 | B4: 소규모 매장 사장 (1인) | C4: 8 | D4: =COUNTIFS(Scenarios!P:P,"P3:*",Scenarios!O:O,"Pass") | E4: =COUNTIFS(Scenarios!P:P,"P3:*",Scenarios!O:O,"Fail") | F4: =COUNTIFS(Scenarios!P:P,"P3:*",Scenarios!O:O,"Skip") | G4: =C4-D4-E4-F4
A5: P4 | B5: 중대형 매장 사장 | C5: 2 | D5: =COUNTIFS(Scenarios!P:P,"P4:*",Scenarios!O:O,"Pass") | E5: =COUNTIFS(Scenarios!P:P,"P4:*",Scenarios!O:O,"Fail") | F5: =COUNTIFS(Scenarios!P:P,"P4:*",Scenarios!O:O,"Skip") | G5: =C5-D5-E5-F5
A6: P5 | B6: 매장 직원 | C6: 4 | D6: =COUNTIFS(Scenarios!P:P,"P5:*",Scenarios!O:O,"Pass") | E6: =COUNTIFS(Scenarios!P:P,"P5:*",Scenarios!O:O,"Fail") | F6: =COUNTIFS(Scenarios!P:P,"P5:*",Scenarios!O:O,"Skip") | G6: =C6-D6-E6-F6
A7: P6 | B7: 슈퍼어드민 | C7: 7 | D7: =COUNTIFS(Scenarios!P:P,"P6:*",Scenarios!O:O,"Pass") | E7: =COUNTIFS(Scenarios!P:P,"P6:*",Scenarios!O:O,"Fail") | F7: =COUNTIFS(Scenarios!P:P,"P6:*",Scenarios!O:O,"Skip") | G7: =C7-D7-E7-F7
A8: P7 | B8: 친구 초대 발급자 | C8: 2 | D8: =COUNTIFS(Scenarios!P:P,"P7:*",Scenarios!O:O,"Pass") | E8: =COUNTIFS(Scenarios!P:P,"P7:*",Scenarios!O:O,"Fail") | F8: =COUNTIFS(Scenarios!P:P,"P7:*",Scenarios!O:O,"Skip") | G8: =C8-D8-E8-F8
A9: P8 | B9: 친구 초대 가입 사용자 | C9: 2 | D9: =COUNTIFS(Scenarios!P:P,"P8:*",Scenarios!O:O,"Pass") | E9: =COUNTIFS(Scenarios!P:P,"P8:*",Scenarios!O:O,"Fail") | F9: =COUNTIFS(Scenarios!P:P,"P8:*",Scenarios!O:O,"Skip") | G9: =C9-D9-E9-F9
A10: P9 | B10: 만 14세 미만 + 보호자 | C10: 3 | D10: =COUNTIFS(Scenarios!P:P,"P9:*",Scenarios!O:O,"Pass") | E10: =COUNTIFS(Scenarios!P:P,"P9:*",Scenarios!O:O,"Fail") | F10: =COUNTIFS(Scenarios!P:P,"P9:*",Scenarios!O:O,"Skip") | G10: =C10-D10-E10-F10
A11: P10 | B11: 소셜 로그인 사용자 | C11: 4 | D11: =COUNTIFS(Scenarios!P:P,"P10:*",Scenarios!O:O,"Pass") | E11: =COUNTIFS(Scenarios!P:P,"P10:*",Scenarios!O:O,"Fail") | F11: =COUNTIFS(Scenarios!P:P,"P10:*",Scenarios!O:O,"Skip") | G11: =C11-D11-E11-F11
A12: P11 | B12: 비밀번호 재설정 | C12: 2 | D12: =COUNTIFS(Scenarios!P:P,"P11:*",Scenarios!O:O,"Pass") | E12: =COUNTIFS(Scenarios!P:P,"P11:*",Scenarios!O:O,"Fail") | F12: =COUNTIFS(Scenarios!P:P,"P11:*",Scenarios!O:O,"Skip") | G12: =C12-D12-E12-F12
A13: P12 | B13: 푸시 토큰 등록 | C13: 3 | D13: =COUNTIFS(Scenarios!P:P,"P12:*",Scenarios!O:O,"Pass") | E13: =COUNTIFS(Scenarios!P:P,"P12:*",Scenarios!O:O,"Fail") | F13: =COUNTIFS(Scenarios!P:P,"P12:*",Scenarios!O:O,"Skip") | G13: =C13-D13-E13-F13
A14: P13 | B14: 1:1 문의 (Support) | C14: 4 | D14: =COUNTIFS(Scenarios!P:P,"P13:*",Scenarios!O:O,"Pass") | E14: =COUNTIFS(Scenarios!P:P,"P13:*",Scenarios!O:O,"Fail") | F14: =COUNTIFS(Scenarios!P:P,"P13:*",Scenarios!O:O,"Skip") | G14: =C14-D14-E14-F14
A15: P14 | B15: 알림 발송 승인 흐름 | C15: 4 | D15: =COUNTIFS(Scenarios!P:P,"P14:*",Scenarios!O:O,"Pass") | E15: =COUNTIFS(Scenarios!P:P,"P14:*",Scenarios!O:O,"Fail") | F15: =COUNTIFS(Scenarios!P:P,"P14:*",Scenarios!O:O,"Skip") | G15: =C15-D15-E15-F15
B16: 합계 | C16: =SUM(C2:C15) | D16: =SUM(D2:D15) | E16: =SUM(E2:E15) | F16: =SUM(F2:F15) | G16: =SUM(G2:G15)
